Traceback (most recent call last):
  File "/home/eligijus/api-book/api_book/lib/python3.8/site-packages/jupyter_cache/executors/utils.py", line 51, in single_nb_execution
    executenb(
  File "/home/eligijus/api-book/api_book/lib/python3.8/site-packages/nbclient/client.py", line 1117, in execute
    return NotebookClient(nb=nb, resources=resources, km=km, **kwargs).execute()
  File "/home/eligijus/api-book/api_book/lib/python3.8/site-packages/nbclient/util.py", line 78, in wrapped
    return just_run(coro(*args, **kwargs))
  File "/home/eligijus/api-book/api_book/lib/python3.8/site-packages/nbclient/util.py", line 57, in just_run
    return loop.run_until_complete(coro)
  File "/usr/lib/python3.8/asyncio/base_events.py", line 616, in run_until_complete
    return future.result()
  File "/home/eligijus/api-book/api_book/lib/python3.8/site-packages/nbclient/client.py", line 558, in async_execute
    await self.async_execute_cell(
  File "/home/eligijus/api-book/api_book/lib/python3.8/site-packages/nbclient/client.py", line 862, in async_execute_cell
    self._check_raise_for_error(cell, exec_reply)
  File "/home/eligijus/api-book/api_book/lib/python3.8/site-packages/nbclient/client.py", line 765, in _check_raise_for_error
    raise CellExecutionError.from_cell_and_msg(cell, exec_reply_content)
nbclient.exceptions.CellExecutionError: An error occurred while executing the following cell:
------------------
# Importing the package 
import requests

# Defining the URL 
url = 'http://localhost:8999'

# Defining the user dict 
user_dict = {
    "username": "eligijus_bujokas",
    "password": "password",
    "email": "eligijus@testmail.com"
}

# Sending the post request to the running API 
response = requests.post(f"{url}/register-user", json=user_dict)

# Getting the user id 
user_id = response.json().get("user_id")

# Printing the response 
print(f"Response code: {response.status_code}; Response: {response.json()}")
------------------

[0;31m---------------------------------------------------------------------------[0m
[0;31mConnectionResetError[0m                      Traceback (most recent call last)
[0;32m~/api-book/api_book/lib/python3.8/site-packages/urllib3/connectionpool.py[0m in [0;36murlopen[0;34m(self, method, url, body, headers, retries, redirect, assert_same_host, timeout, pool_timeout, release_conn, chunked, body_pos, **response_kw)[0m
[1;32m    698[0m             [0;31m# Make the request on the httplib connection object.[0m[0;34m[0m[0;34m[0m[0;34m[0m[0m
[0;32m--> 699[0;31m             httplib_response = self._make_request(
[0m[1;32m    700[0m                 [0mconn[0m[0;34m,[0m[0;34m[0m[0;34m[0m[0m

[0;32m~/api-book/api_book/lib/python3.8/site-packages/urllib3/connectionpool.py[0m in [0;36m_make_request[0;34m(self, conn, method, url, timeout, chunked, **httplib_request_kw)[0m
[1;32m    444[0m                     [0;31m# Otherwise it looks like a bug in the code.[0m[0;34m[0m[0;34m[0m[0;34m[0m[0m
[0;32m--> 445[0;31m                     [0msix[0m[0;34m.[0m[0mraise_from[0m[0;34m([0m[0me[0m[0;34m,[0m [0;32mNone[0m[0;34m)[0m[0;34m[0m[0;34m[0m[0m
[0m[1;32m    446[0m         [0;32mexcept[0m [0;34m([0m[0mSocketTimeout[0m[0;34m,[0m [0mBaseSSLError[0m[0;34m,[0m [0mSocketError[0m[0;34m)[0m [0;32mas[0m [0me[0m[0;34m:[0m[0;34m[0m[0;34m[0m[0m

[0;32m~/api-book/api_book/lib/python3.8/site-packages/urllib3/packages/six.py[0m in [0;36mraise_from[0;34m(value, from_value)[0m

[0;32m~/api-book/api_book/lib/python3.8/site-packages/urllib3/connectionpool.py[0m in [0;36m_make_request[0;34m(self, conn, method, url, timeout, chunked, **httplib_request_kw)[0m
[1;32m    439[0m                 [0;32mtry[0m[0;34m:[0m[0;34m[0m[0;34m[0m[0m
[0;32m--> 440[0;31m                     [0mhttplib_response[0m [0;34m=[0m [0mconn[0m[0;34m.[0m[0mgetresponse[0m[0;34m([0m[0;34m)[0m[0;34m[0m[0;34m[0m[0m
[0m[1;32m    441[0m                 [0;32mexcept[0m [0mBaseException[0m [0;32mas[0m [0me[0m[0;34m:[0m[0;34m[0m[0;34m[0m[0m

[0;32m/usr/lib/python3.8/http/client.py[0m in [0;36mgetresponse[0;34m(self)[0m
[1;32m   1347[0m             [0;32mtry[0m[0;34m:[0m[0;34m[0m[0;34m[0m[0m
[0;32m-> 1348[0;31m                 [0mresponse[0m[0;34m.[0m[0mbegin[0m[0;34m([0m[0;34m)[0m[0;34m[0m[0;34m[0m[0m
[0m[1;32m   1349[0m             [0;32mexcept[0m [0mConnectionError[0m[0;34m:[0m[0;34m[0m[0;34m[0m[0m

[0;32m/usr/lib/python3.8/http/client.py[0m in [0;36mbegin[0;34m(self)[0m
[1;32m    315[0m         [0;32mwhile[0m [0;32mTrue[0m[0;34m:[0m[0;34m[0m[0;34m[0m[0m
[0;32m--> 316[0;31m             [0mversion[0m[0;34m,[0m [0mstatus[0m[0;34m,[0m [0mreason[0m [0;34m=[0m [0mself[0m[0;34m.[0m[0m_read_status[0m[0;34m([0m[0;34m)[0m[0;34m[0m[0;34m[0m[0m
[0m[1;32m    317[0m             [0;32mif[0m [0mstatus[0m [0;34m!=[0m [0mCONTINUE[0m[0;34m:[0m[0;34m[0m[0;34m[0m[0m

[0;32m/usr/lib/python3.8/http/client.py[0m in [0;36m_read_status[0;34m(self)[0m
[1;32m    276[0m     [0;32mdef[0m [0m_read_status[0m[0;34m([0m[0mself[0m[0;34m)[0m[0;34m:[0m[0;34m[0m[0;34m[0m[0m
[0;32m--> 277[0;31m         [0mline[0m [0;34m=[0m [0mstr[0m[0;34m([0m[0mself[0m[0;34m.[0m[0mfp[0m[0;34m.[0m[0mreadline[0m[0;34m([0m[0m_MAXLINE[0m [0;34m+[0m [0;36m1[0m[0;34m)[0m[0;34m,[0m [0;34m"iso-8859-1"[0m[0;34m)[0m[0;34m[0m[0;34m[0m[0m
[0m[1;32m    278[0m         [0;32mif[0m [0mlen[0m[0;34m([0m[0mline[0m[0;34m)[0m [0;34m>[0m [0m_MAXLINE[0m[0;34m:[0m[0;34m[0m[0;34m[0m[0m

[0;32m/usr/lib/python3.8/socket.py[0m in [0;36mreadinto[0;34m(self, b)[0m
[1;32m    668[0m             [0;32mtry[0m[0;34m:[0m[0;34m[0m[0;34m[0m[0m
[0;32m--> 669[0;31m                 [0;32mreturn[0m [0mself[0m[0;34m.[0m[0m_sock[0m[0;34m.[0m[0mrecv_into[0m[0;34m([0m[0mb[0m[0;34m)[0m[0;34m[0m[0;34m[0m[0m
[0m[1;32m    670[0m             [0;32mexcept[0m [0mtimeout[0m[0;34m:[0m[0;34m[0m[0;34m[0m[0m

[0;31mConnectionResetError[0m: [Errno 104] Connection reset by peer

During handling of the above exception, another exception occurred:

[0;31mProtocolError[0m                             Traceback (most recent call last)
[0;32m~/api-book/api_book/lib/python3.8/site-packages/requests/adapters.py[0m in [0;36msend[0;34m(self, request, stream, timeout, verify, cert, proxies)[0m
[1;32m    438[0m             [0;32mif[0m [0;32mnot[0m [0mchunked[0m[0;34m:[0m[0;34m[0m[0;34m[0m[0m
[0;32m--> 439[0;31m                 resp = conn.urlopen(
[0m[1;32m    440[0m                     [0mmethod[0m[0;34m=[0m[0mrequest[0m[0;34m.[0m[0mmethod[0m[0;34m,[0m[0;34m[0m[0;34m[0m[0m

[0;32m~/api-book/api_book/lib/python3.8/site-packages/urllib3/connectionpool.py[0m in [0;36murlopen[0;34m(self, method, url, body, headers, retries, redirect, assert_same_host, timeout, pool_timeout, release_conn, chunked, body_pos, **response_kw)[0m
[1;32m    754[0m [0;34m[0m[0m
[0;32m--> 755[0;31m             retries = retries.increment(
[0m[1;32m    756[0m                 [0mmethod[0m[0;34m,[0m [0murl[0m[0;34m,[0m [0merror[0m[0;34m=[0m[0me[0m[0;34m,[0m [0m_pool[0m[0;34m=[0m[0mself[0m[0;34m,[0m [0m_stacktrace[0m[0;34m=[0m[0msys[0m[0;34m.[0m[0mexc_info[0m[0;34m([0m[0;34m)[0m[0;34m[[0m[0;36m2[0m[0;34m][0m[0;34m[0m[0;34m[0m[0m

[0;32m~/api-book/api_book/lib/python3.8/site-packages/urllib3/util/retry.py[0m in [0;36mincrement[0;34m(self, method, url, response, error, _pool, _stacktrace)[0m
[1;32m    531[0m             [0;32mif[0m [0mread[0m [0;32mis[0m [0;32mFalse[0m [0;32mor[0m [0;32mnot[0m [0mself[0m[0;34m.[0m[0m_is_method_retryable[0m[0;34m([0m[0mmethod[0m[0;34m)[0m[0;34m:[0m[0;34m[0m[0;34m[0m[0m
[0;32m--> 532[0;31m                 [0;32mraise[0m [0msix[0m[0;34m.[0m[0mreraise[0m[0;34m([0m[0mtype[0m[0;34m([0m[0merror[0m[0;34m)[0m[0;34m,[0m [0merror[0m[0;34m,[0m [0m_stacktrace[0m[0;34m)[0m[0;34m[0m[0;34m[0m[0m
[0m[1;32m    533[0m             [0;32melif[0m [0mread[0m [0;32mis[0m [0;32mnot[0m [0;32mNone[0m[0;34m:[0m[0;34m[0m[0;34m[0m[0m

[0;32m~/api-book/api_book/lib/python3.8/site-packages/urllib3/packages/six.py[0m in [0;36mreraise[0;34m(tp, value, tb)[0m
[1;32m    768[0m             [0;32mif[0m [0mvalue[0m[0;34m.[0m[0m__traceback__[0m [0;32mis[0m [0;32mnot[0m [0mtb[0m[0;34m:[0m[0;34m[0m[0;34m[0m[0m
[0;32m--> 769[0;31m                 [0;32mraise[0m [0mvalue[0m[0;34m.[0m[0mwith_traceback[0m[0;34m([0m[0mtb[0m[0;34m)[0m[0;34m[0m[0;34m[0m[0m
[0m[1;32m    770[0m             [0;32mraise[0m [0mvalue[0m[0;34m[0m[0;34m[0m[0m

[0;32m~/api-book/api_book/lib/python3.8/site-packages/urllib3/connectionpool.py[0m in [0;36murlopen[0;34m(self, method, url, body, headers, retries, redirect, assert_same_host, timeout, pool_timeout, release_conn, chunked, body_pos, **response_kw)[0m
[1;32m    698[0m             [0;31m# Make the request on the httplib connection object.[0m[0;34m[0m[0;34m[0m[0;34m[0m[0m
[0;32m--> 699[0;31m             httplib_response = self._make_request(
[0m[1;32m    700[0m                 [0mconn[0m[0;34m,[0m[0;34m[0m[0;34m[0m[0m

[0;32m~/api-book/api_book/lib/python3.8/site-packages/urllib3/connectionpool.py[0m in [0;36m_make_request[0;34m(self, conn, method, url, timeout, chunked, **httplib_request_kw)[0m
[1;32m    444[0m                     [0;31m# Otherwise it looks like a bug in the code.[0m[0;34m[0m[0;34m[0m[0;34m[0m[0m
[0;32m--> 445[0;31m                     [0msix[0m[0;34m.[0m[0mraise_from[0m[0;34m([0m[0me[0m[0;34m,[0m [0;32mNone[0m[0;34m)[0m[0;34m[0m[0;34m[0m[0m
[0m[1;32m    446[0m         [0;32mexcept[0m [0;34m([0m[0mSocketTimeout[0m[0;34m,[0m [0mBaseSSLError[0m[0;34m,[0m [0mSocketError[0m[0;34m)[0m [0;32mas[0m [0me[0m[0;34m:[0m[0;34m[0m[0;34m[0m[0m

[0;32m~/api-book/api_book/lib/python3.8/site-packages/urllib3/packages/six.py[0m in [0;36mraise_from[0;34m(value, from_value)[0m

[0;32m~/api-book/api_book/lib/python3.8/site-packages/urllib3/connectionpool.py[0m in [0;36m_make_request[0;34m(self, conn, method, url, timeout, chunked, **httplib_request_kw)[0m
[1;32m    439[0m                 [0;32mtry[0m[0;34m:[0m[0;34m[0m[0;34m[0m[0m
[0;32m--> 440[0;31m                     [0mhttplib_response[0m [0;34m=[0m [0mconn[0m[0;34m.[0m[0mgetresponse[0m[0;34m([0m[0;34m)[0m[0;34m[0m[0;34m[0m[0m
[0m[1;32m    441[0m                 [0;32mexcept[0m [0mBaseException[0m [0;32mas[0m [0me[0m[0;34m:[0m[0;34m[0m[0;34m[0m[0m

[0;32m/usr/lib/python3.8/http/client.py[0m in [0;36mgetresponse[0;34m(self)[0m
[1;32m   1347[0m             [0;32mtry[0m[0;34m:[0m[0;34m[0m[0;34m[0m[0m
[0;32m-> 1348[0;31m                 [0mresponse[0m[0;34m.[0m[0mbegin[0m[0;34m([0m[0;34m)[0m[0;34m[0m[0;34m[0m[0m
[0m[1;32m   1349[0m             [0;32mexcept[0m [0mConnectionError[0m[0;34m:[0m[0;34m[0m[0;34m[0m[0m

[0;32m/usr/lib/python3.8/http/client.py[0m in [0;36mbegin[0;34m(self)[0m
[1;32m    315[0m         [0;32mwhile[0m [0;32mTrue[0m[0;34m:[0m[0;34m[0m[0;34m[0m[0m
[0;32m--> 316[0;31m             [0mversion[0m[0;34m,[0m [0mstatus[0m[0;34m,[0m [0mreason[0m [0;34m=[0m [0mself[0m[0;34m.[0m[0m_read_status[0m[0;34m([0m[0;34m)[0m[0;34m[0m[0;34m[0m[0m
[0m[1;32m    317[0m             [0;32mif[0m [0mstatus[0m [0;34m!=[0m [0mCONTINUE[0m[0;34m:[0m[0;34m[0m[0;34m[0m[0m

[0;32m/usr/lib/python3.8/http/client.py[0m in [0;36m_read_status[0;34m(self)[0m
[1;32m    276[0m     [0;32mdef[0m [0m_read_status[0m[0;34m([0m[0mself[0m[0;34m)[0m[0;34m:[0m[0;34m[0m[0;34m[0m[0m
[0;32m--> 277[0;31m         [0mline[0m [0;34m=[0m [0mstr[0m[0;34m([0m[0mself[0m[0;34m.[0m[0mfp[0m[0;34m.[0m[0mreadline[0m[0;34m([0m[0m_MAXLINE[0m [0;34m+[0m [0;36m1[0m[0;34m)[0m[0;34m,[0m [0;34m"iso-8859-1"[0m[0;34m)[0m[0;34m[0m[0;34m[0m[0m
[0m[1;32m    278[0m         [0;32mif[0m [0mlen[0m[0;34m([0m[0mline[0m[0;34m)[0m [0;34m>[0m [0m_MAXLINE[0m[0;34m:[0m[0;34m[0m[0;34m[0m[0m

[0;32m/usr/lib/python3.8/socket.py[0m in [0;36mreadinto[0;34m(self, b)[0m
[1;32m    668[0m             [0;32mtry[0m[0;34m:[0m[0;34m[0m[0;34m[0m[0m
[0;32m--> 669[0;31m                 [0;32mreturn[0m [0mself[0m[0;34m.[0m[0m_sock[0m[0;34m.[0m[0mrecv_into[0m[0;34m([0m[0mb[0m[0;34m)[0m[0;34m[0m[0;34m[0m[0m
[0m[1;32m    670[0m             [0;32mexcept[0m [0mtimeout[0m[0;34m:[0m[0;34m[0m[0;34m[0m[0m

[0;31mProtocolError[0m: ('Connection aborted.', ConnectionResetError(104, 'Connection reset by peer'))

During handling of the above exception, another exception occurred:

[0;31mConnectionError[0m                           Traceback (most recent call last)
[0;32m/tmp/ipykernel_15462/2725684868.py[0m in [0;36m<module>[0;34m[0m
[1;32m     13[0m [0;34m[0m[0m
[1;32m     14[0m [0;31m# Sending the post request to the running API[0m[0;34m[0m[0;34m[0m[0;34m[0m[0m
[0;32m---> 15[0;31m [0mresponse[0m [0;34m=[0m [0mrequests[0m[0;34m.[0m[0mpost[0m[0;34m([0m[0;34mf"{url}/register-user"[0m[0;34m,[0m [0mjson[0m[0;34m=[0m[0muser_dict[0m[0;34m)[0m[0;34m[0m[0;34m[0m[0m
[0m[1;32m     16[0m [0;34m[0m[0m
[1;32m     17[0m [0;31m# Getting the user id[0m[0;34m[0m[0;34m[0m[0;34m[0m[0m

[0;32m~/api-book/api_book/lib/python3.8/site-packages/requests/api.py[0m in [0;36mpost[0;34m(url, data, json, **kwargs)[0m
[1;32m    115[0m     """
[1;32m    116[0m [0;34m[0m[0m
[0;32m--> 117[0;31m     [0;32mreturn[0m [0mrequest[0m[0;34m([0m[0;34m'post'[0m[0;34m,[0m [0murl[0m[0;34m,[0m [0mdata[0m[0;34m=[0m[0mdata[0m[0;34m,[0m [0mjson[0m[0;34m=[0m[0mjson[0m[0;34m,[0m [0;34m**[0m[0mkwargs[0m[0;34m)[0m[0;34m[0m[0;34m[0m[0m
[0m[1;32m    118[0m [0;34m[0m[0m
[1;32m    119[0m [0;34m[0m[0m

[0;32m~/api-book/api_book/lib/python3.8/site-packages/requests/api.py[0m in [0;36mrequest[0;34m(method, url, **kwargs)[0m
[1;32m     59[0m     [0;31m# cases, and look like a memory leak in others.[0m[0;34m[0m[0;34m[0m[0;34m[0m[0m
[1;32m     60[0m     [0;32mwith[0m [0msessions[0m[0;34m.[0m[0mSession[0m[0;34m([0m[0;34m)[0m [0;32mas[0m [0msession[0m[0;34m:[0m[0;34m[0m[0;34m[0m[0m
[0;32m---> 61[0;31m         [0;32mreturn[0m [0msession[0m[0;34m.[0m[0mrequest[0m[0;34m([0m[0mmethod[0m[0;34m=[0m[0mmethod[0m[0;34m,[0m [0murl[0m[0;34m=[0m[0murl[0m[0;34m,[0m [0;34m**[0m[0mkwargs[0m[0;34m)[0m[0;34m[0m[0;34m[0m[0m
[0m[1;32m     62[0m [0;34m[0m[0m
[1;32m     63[0m [0;34m[0m[0m

[0;32m~/api-book/api_book/lib/python3.8/site-packages/requests/sessions.py[0m in [0;36mrequest[0;34m(self, method, url, params, data, headers, cookies, files, auth, timeout, allow_redirects, proxies, hooks, stream, verify, cert, json)[0m
[1;32m    540[0m         }
[1;32m    541[0m         [0msend_kwargs[0m[0;34m.[0m[0mupdate[0m[0;34m([0m[0msettings[0m[0;34m)[0m[0;34m[0m[0;34m[0m[0m
[0;32m--> 542[0;31m         [0mresp[0m [0;34m=[0m [0mself[0m[0;34m.[0m[0msend[0m[0;34m([0m[0mprep[0m[0;34m,[0m [0;34m**[0m[0msend_kwargs[0m[0;34m)[0m[0;34m[0m[0;34m[0m[0m
[0m[1;32m    543[0m [0;34m[0m[0m
[1;32m    544[0m         [0;32mreturn[0m [0mresp[0m[0;34m[0m[0;34m[0m[0m

[0;32m~/api-book/api_book/lib/python3.8/site-packages/requests/sessions.py[0m in [0;36msend[0;34m(self, request, **kwargs)[0m
[1;32m    653[0m [0;34m[0m[0m
[1;32m    654[0m         [0;31m# Send the request[0m[0;34m[0m[0;34m[0m[0;34m[0m[0m
[0;32m--> 655[0;31m         [0mr[0m [0;34m=[0m [0madapter[0m[0;34m.[0m[0msend[0m[0;34m([0m[0mrequest[0m[0;34m,[0m [0;34m**[0m[0mkwargs[0m[0;34m)[0m[0;34m[0m[0;34m[0m[0m
[0m[1;32m    656[0m [0;34m[0m[0m
[1;32m    657[0m         [0;31m# Total elapsed time of the request (approximately)[0m[0;34m[0m[0;34m[0m[0;34m[0m[0m

[0;32m~/api-book/api_book/lib/python3.8/site-packages/requests/adapters.py[0m in [0;36msend[0;34m(self, request, stream, timeout, verify, cert, proxies)[0m
[1;32m    496[0m [0;34m[0m[0m
[1;32m    497[0m         [0;32mexcept[0m [0;34m([0m[0mProtocolError[0m[0;34m,[0m [0msocket[0m[0;34m.[0m[0merror[0m[0;34m)[0m [0;32mas[0m [0merr[0m[0;34m:[0m[0;34m[0m[0;34m[0m[0m
[0;32m--> 498[0;31m             [0;32mraise[0m [0mConnectionError[0m[0;34m([0m[0merr[0m[0;34m,[0m [0mrequest[0m[0;34m=[0m[0mrequest[0m[0;34m)[0m[0;34m[0m[0;34m[0m[0m
[0m[1;32m    499[0m [0;34m[0m[0m
[1;32m    500[0m         [0;32mexcept[0m [0mMaxRetryError[0m [0;32mas[0m [0me[0m[0;34m:[0m[0;34m[0m[0;34m[0m[0m

[0;31mConnectionError[0m: ('Connection aborted.', ConnectionResetError(104, 'Connection reset by peer'))
ConnectionError: ('Connection aborted.', ConnectionResetError(104, 'Connection reset by peer'))

