Traceback (most recent call last):
  File "/home/eligijus/api-book/api_book/lib/python3.8/site-packages/jupyter_cache/executors/utils.py", line 51, in single_nb_execution
    executenb(
  File "/home/eligijus/api-book/api_book/lib/python3.8/site-packages/nbclient/client.py", line 1117, in execute
    return NotebookClient(nb=nb, resources=resources, km=km, **kwargs).execute()
  File "/home/eligijus/api-book/api_book/lib/python3.8/site-packages/nbclient/util.py", line 78, in wrapped
    return just_run(coro(*args, **kwargs))
  File "/home/eligijus/api-book/api_book/lib/python3.8/site-packages/nbclient/util.py", line 57, in just_run
    return loop.run_until_complete(coro)
  File "/usr/lib/python3.8/asyncio/base_events.py", line 616, in run_until_complete
    return future.result()
  File "/home/eligijus/api-book/api_book/lib/python3.8/site-packages/nbclient/client.py", line 558, in async_execute
    await self.async_execute_cell(
  File "/home/eligijus/api-book/api_book/lib/python3.8/site-packages/nbclient/client.py", line 862, in async_execute_cell
    self._check_raise_for_error(cell, exec_reply)
  File "/home/eligijus/api-book/api_book/lib/python3.8/site-packages/nbclient/client.py", line 765, in _check_raise_for_error
    raise CellExecutionError.from_cell_and_msg(cell, exec_reply_content)
nbclient.exceptions.CellExecutionError: An error occurred while executing the following cell:
------------------
# Import the API querying lib
import requests

# Defining some numbers and roots 
numbers = [1, 2, 3, 4, 5]
roots = [0.5, 0.4, 0.3, 0.2, 0.1]

# Zipping for the loop
numbers_and_roots = zip(numbers, roots)

for number_and_root in numbers_and_roots:
    # Unpacking the numbers and roots
    number, root = number_and_root

    # Creating the request
    response = requests.get(f'http://localhost:8000/root?number={number}&n={root}')

    # Checking the response status code
    print(f"Root {root} of {number}: {response.json()['root']}")
------------------

[0;31m---------------------------------------------------------------------------[0m
[0;31mKeyError[0m                                  Traceback (most recent call last)
[0;32m/tmp/ipykernel_19579/3307253417.py[0m in [0;36m<module>[0;34m[0m
[1;32m     17[0m [0;34m[0m[0m
[1;32m     18[0m     [0;31m# Checking the response status code[0m[0;34m[0m[0;34m[0m[0;34m[0m[0m
[0;32m---> 19[0;31m     [0mprint[0m[0;34m([0m[0;34mf"Root {root} of {number}: {response.json()['root']}"[0m[0;34m)[0m[0;34m[0m[0;34m[0m[0m
[0m
[0;31mKeyError[0m: 'root'
KeyError: 'root'

